[2023-02-23 11:09:44,842]-[Assert.py]-[line:17]-ERROR: 断言失败----验证值为： 1001001, 结果为：200 
Traceback (most recent call last):
  File "C:\Users\Administrator\PycharmProjects\API_auto_test\common\Assert.py", line 14, in assert_equal
    assert value_1 == value_2
AssertionError
[2023-02-23 19:11:10,130]-[Assert.py]-[line:17]-ERROR: 断言失败----验证值为： 101, 结果为：200 
Traceback (most recent call last):
  File "C:\Users\Administrator\PycharmProjects\API_auto_test\common\Assert.py", line 14, in assert_equal
    assert value_1 == value_2
AssertionError
[2023-02-23 19:11:49,270]-[Assert.py]-[line:17]-ERROR: 断言失败----验证值为： 101, 结果为：200 
Traceback (most recent call last):
  File "C:\Users\Administrator\PycharmProjects\API_auto_test\common\Assert.py", line 14, in assert_equal
    assert value_1 == value_2
AssertionError
[2023-02-23 19:12:02,240]-[Assert.py]-[line:17]-ERROR: 断言失败----验证值为： 101, 结果为：200 
Traceback (most recent call last):
  File "C:\Users\Administrator\PycharmProjects\API_auto_test\common\Assert.py", line 14, in assert_equal
    assert value_1 == value_2
AssertionError
[2023-02-23 19:14:45,865]-[Assert.py]-[line:17]-ERROR: 断言失败----验证值为： 101, 结果为：200 
Traceback (most recent call last):
  File "C:\Users\Administrator\PycharmProjects\API_auto_test\common\Assert.py", line 14, in assert_equal
    assert value_1 == value_2
AssertionError
[2023-02-23 19:19:29,916]-[Assert.py]-[line:17]-ERROR: 断言失败----验证值为： 101, 结果为：200 
Traceback (most recent call last):
  File "C:\Users\Administrator\PycharmProjects\API_auto_test\common\Assert.py", line 14, in assert_equal
    assert value_1 == value_2
AssertionError
[2023-02-23 19:20:15,095]-[Assert.py]-[line:17]-ERROR: 断言失败----验证值为： 101, 结果为：200 
Traceback (most recent call last):
  File "C:\Users\Administrator\PycharmProjects\API_auto_test\common\Assert.py", line 14, in assert_equal
    assert value_1 == value_2
AssertionError
[2023-02-23 19:23:35,924]-[Assert.py]-[line:17]-ERROR: 断言失败----验证值为： 500, 结果为：200 
Traceback (most recent call last):
  File "C:\Users\Administrator\PycharmProjects\API_auto_test\common\Assert.py", line 14, in assert_equal
    assert value_1 == value_2
AssertionError
[2023-02-23 19:23:55,476]-[Assert.py]-[line:17]-ERROR: 断言失败----验证值为： 500, 结果为：200 
Traceback (most recent call last):
  File "C:\Users\Administrator\PycharmProjects\API_auto_test\common\Assert.py", line 14, in assert_equal
    assert value_1 == value_2
AssertionError
[2023-02-23 19:24:20,059]-[Request.py]-[line:45]-ERROR: Post请求接口：https://mrpa-test.ai-rtc.com:8082/plat/api/skill/version/save出错! request() got an unexpected keyword argument 'file'
Traceback (most recent call last):
  File "C:\Users\Administrator\PycharmProjects\API_auto_test\common\Request.py", line 34, in post_method
    response = requests.post(url=url, data=data, json=json, **kwargs)
  File "C:\Users\Administrator\PycharmProjects\clpytest\venv\lib\site-packages\requests\api.py", line 117, in post
    return request('post', url, data=data, json=json, **kwargs)
  File "C:\Users\Administrator\PycharmProjects\clpytest\venv\lib\site-packages\requests\api.py", line 61, in request
    return session.request(method=method, url=url, **kwargs)
TypeError: request() got an unexpected keyword argument 'file'
[2023-02-23 19:24:31,828]-[Request.py]-[line:45]-ERROR: Post请求接口：https://mrpa-test.ai-rtc.com:8082/plat/api/skill/version/save出错! cannot encode objects that are not 2-tuples
Traceback (most recent call last):
  File "C:\Users\Administrator\PycharmProjects\API_auto_test\common\Request.py", line 34, in post_method
    response = requests.post(url=url, data=data, json=json, **kwargs)
  File "C:\Users\Administrator\PycharmProjects\clpytest\venv\lib\site-packages\requests\api.py", line 117, in post
    return request('post', url, data=data, json=json, **kwargs)
  File "C:\Users\Administrator\PycharmProjects\clpytest\venv\lib\site-packages\requests\api.py", line 61, in request
    return session.request(method=method, url=url, **kwargs)
  File "C:\Users\Administrator\PycharmProjects\clpytest\venv\lib\site-packages\requests\sessions.py", line 515, in request
    prep = self.prepare_request(req)
  File "C:\Users\Administrator\PycharmProjects\clpytest\venv\lib\site-packages\requests\sessions.py", line 453, in prepare_request
    hooks=merge_hooks(request.hooks, self.hooks),
  File "C:\Users\Administrator\PycharmProjects\clpytest\venv\lib\site-packages\requests\models.py", line 321, in prepare
    self.prepare_body(data, files, json)
  File "C:\Users\Administrator\PycharmProjects\clpytest\venv\lib\site-packages\requests\models.py", line 514, in prepare_body
    (body, content_type) = self._encode_files(files, data)
  File "C:\Users\Administrator\PycharmProjects\clpytest\venv\lib\site-packages\requests\models.py", line 128, in _encode_files
    files = to_key_val_list(files or {})
  File "C:\Users\Administrator\PycharmProjects\clpytest\venv\lib\site-packages\requests\utils.py", line 343, in to_key_val_list
    raise ValueError('cannot encode objects that are not 2-tuples')
ValueError: cannot encode objects that are not 2-tuples
[2023-02-23 19:25:16,802]-[Assert.py]-[line:17]-ERROR: 断言失败----验证值为： 101, 结果为：200 
Traceback (most recent call last):
  File "C:\Users\Administrator\PycharmProjects\API_auto_test\common\Assert.py", line 14, in assert_equal
    assert value_1 == value_2
AssertionError
[2023-02-23 19:29:24,967]-[Assert.py]-[line:17]-ERROR: 断言失败----验证值为： 500, 结果为：200 
Traceback (most recent call last):
  File "C:\Users\Administrator\PycharmProjects\API_auto_test\common\Assert.py", line 14, in assert_equal
    assert value_1 == value_2
AssertionError
[2023-02-23 19:30:20,267]-[Assert.py]-[line:17]-ERROR: 断言失败----验证值为： 500, 结果为：200 
Traceback (most recent call last):
  File "C:\Users\Administrator\PycharmProjects\API_auto_test\common\Assert.py", line 14, in assert_equal
    assert value_1 == value_2
AssertionError
[2023-02-23 19:32:20,887]-[Assert.py]-[line:17]-ERROR: 断言失败----验证值为： 101, 结果为：200 
Traceback (most recent call last):
  File "C:\Users\Administrator\PycharmProjects\API_auto_test\common\Assert.py", line 14, in assert_equal
    assert value_1 == value_2
AssertionError
[2023-02-23 19:34:25,766]-[Assert.py]-[line:17]-ERROR: 断言失败----验证值为： 101, 结果为：200 
Traceback (most recent call last):
  File "C:\Users\Administrator\PycharmProjects\API_auto_test\common\Assert.py", line 14, in assert_equal
    assert value_1 == value_2
AssertionError
[2023-02-23 19:35:16,361]-[Assert.py]-[line:17]-ERROR: 断言失败----验证值为： 101, 结果为：200 
Traceback (most recent call last):
  File "C:\Users\Administrator\PycharmProjects\API_auto_test\common\Assert.py", line 14, in assert_equal
    assert value_1 == value_2
AssertionError
[2023-02-23 19:36:22,751]-[Assert.py]-[line:17]-ERROR: 断言失败----验证值为： 101, 结果为：200 
Traceback (most recent call last):
  File "C:\Users\Administrator\PycharmProjects\API_auto_test\common\Assert.py", line 14, in assert_equal
    assert value_1 == value_2
AssertionError
[2023-02-23 19:41:05,317]-[Assert.py]-[line:17]-ERROR: 断言失败----验证值为： 101, 结果为：200 
Traceback (most recent call last):
  File "C:\Users\Administrator\PycharmProjects\API_auto_test\common\Assert.py", line 14, in assert_equal
    assert value_1 == value_2
AssertionError
[2023-02-23 19:42:29,376]-[Assert.py]-[line:17]-ERROR: 断言失败----验证值为： 101, 结果为：200 
Traceback (most recent call last):
  File "C:\Users\Administrator\PycharmProjects\API_auto_test\common\Assert.py", line 14, in assert_equal
    assert value_1 == value_2
AssertionError
